<mujoco model="unnamed_model">
  <compiler autolimits="true" angle="radian"/>
  <option integrator="implicitfast"/>
  <default>
    <default class="/"/>
    <default class="xarm5/">
      <default class="xarm5/xarm5">
        <joint axis="0 0 1" range="-6.2831900000000003 6.2831900000000003" armature="0.10000000000000001" frictionloss="1"/>
        <geom type="mesh" material="xarm5/white"/>
        <general ctrlrange="-6.2831900000000003 6.2831900000000003" biastype="affine"/>
        <default class="xarm5/size1">
          <joint damping="10"/>
          <general forcerange="-50 50" gainprm="1500" biasprm="0 -1500 -150"/>
        </default>
        <default class="xarm5/size2">
          <joint damping="5"/>
          <general forcerange="-30 30" gainprm="1000" biasprm="0 -1000 -100"/>
        </default>
        <default class="xarm5/size3">
          <joint damping="2"/>
          <general forcerange="-20 20" gainprm="800" biasprm="0 -800 -80"/>
        </default>
        <default class="xarm5/spring_link">
          <joint stiffness="0.050000000000000003" range="0 0.84999999999999998" springref="2.6200000000000001" damping="0.00125"/>
        </default>
        <default class="xarm5/driver">
          <joint solreflimit="0.0050000000000000001 1" range="0 0.84999999999999998" armature="0.0050000000000000001" damping="0.10000000000000001"/>
        </default>
        <default class="xarm5/follower">
          <joint solreflimit="0.0050000000000000001 1" range="0 0.84999999999999998"/>
        </default>
        <default class="xarm5/visual">
          <geom type="mesh" contype="0" conaffinity="0" group="2"/>
        </default>
        <default class="xarm5/collision">
          <geom type="mesh" group="3"/>
          <default class="xarm5/pad_box1">
            <geom type="box" priority="1" size="0.014999999999999999 0.002 0.0094999999999999998" rgba="0 0.10000000000000001 0.69999999999999996 1" friction="0.69999999999999996" mass="0" solref="0.0040000000000000001 1" solimp="0.94999999999999996 0.98999999999999999 0.001"/>
          </default>
          <default class="xarm5/pad_box2">
            <geom type="box" priority="1" size="0.014999999999999999 0.002 0.0094999999999999998" rgba="0 0.5 0.5 1" friction="0.59999999999999998" mass="0" solref="0.0040000000000000001 1" solimp="0.94999999999999996 0.98999999999999999 0.001"/>
          </default>
        </default>
      </default>
    </default>
  </default>
  <asset>
    <material name="xarm5/white" class="xarm5/" rgba="1 1 1 1"/>
    <material name="xarm5/gray" class="xarm5/" rgba="0.753 0.753 0.753 1"/>
    <material name="xarm5/black" class="xarm5/" rgba="0.14899999999999999 0.14899999999999999 0.14899999999999999 1"/>
    <mesh name="xarm5/link_base" class="xarm5/" file="link_base-64ce9b2e95217e12eff544a42b31271f9e6b7571.stl" scale="0.001 0.001 0.001"/>
    <mesh name="xarm5/link1" class="xarm5/" file="link1-2bbee38d05b52ec7c04526bfd7774c77fd1b8beb.stl" scale="0.001 0.001 0.001"/>
    <mesh name="xarm5/link2" class="xarm5/" file="link2-1756688c45d203eec0ab7cec1fe6fe7b412db415.stl" scale="0.001 0.001 0.001"/>
    <mesh name="xarm5/link3" class="xarm5/" file="link3-8029d5e488db26128d63069dd8ea7e782990c373.stl" scale="0.001 0.001 0.001"/>
    <mesh name="xarm5/link4" class="xarm5/" file="link4-f3547a71e76102cffeb9e0db50b74a2d02b500e9.stl" scale="0.001 0.001 0.001"/>
    <mesh name="xarm5/link5" class="xarm5/" file="link5-d9eabf162f99c4f6ebc3a74e33e5449ad5deddd1.stl" scale="0.001 0.001 0.001"/>
    <mesh name="xarm5/link6" class="xarm5/" file="link6-0465cf3c7f378d49e4a8cbb7e03af40a61cafd5c.stl" scale="0.001 0.001 0.001"/>
    <mesh name="xarm5/end_tool" class="xarm5/" file="end_tool-fba88989e12d718c4e6776399e40b7df4c85f363.stl"/>
    <mesh name="xarm5/base_link" class="xarm5/" file="base_link-d452ec9c2e3ab46e11f888b2f464c736ad508f3a.stl"/>
    <mesh name="xarm5/left_outer_knuckle" class="xarm5/" file="left_outer_knuckle-e36b948e1ddeda6293ba6a857a0af46ebd01577e.stl"/>
    <mesh name="xarm5/left_finger" class="xarm5/" file="left_finger-998386065252ae2753e808ac4441721a36844c25.stl"/>
    <mesh name="xarm5/left_inner_knuckle" class="xarm5/" file="left_inner_knuckle-6ba918569ea7400d8d60375872b1c80637af6bf9.stl"/>
    <mesh name="xarm5/right_outer_knuckle" class="xarm5/" file="right_outer_knuckle-2469f2cd96cfaff3904c1e529638c369d012554b.stl"/>
    <mesh name="xarm5/right_finger" class="xarm5/" file="right_finger-7f7b2cca4eb2d392610db5dcb8c48b8d21feeffb.stl"/>
    <mesh name="xarm5/right_inner_knuckle" class="xarm5/" file="right_inner_knuckle-de1bc22588febf14e803ded214697e42ffe235ef.stl"/>
  </asset>
  <worldbody>
    <body name="xarm5/">
      <body name="xarm5/link_base" childclass="xarm5/xarm5" pos="0 0 0.12">
        <inertial pos="-0.021131 -0.0016302000000000001 0.056487999999999997" quat="0.69684299999999999 0.20175999999999999 0.10388 0.68037599999999998" mass="0.88556000000000001" diaginertia="0.00382023 0.0033528199999999998 0.0016772499999999999"/>
        <geom name="xarm5//unnamed_geom_0" mesh="xarm5/link_base"/>
        <body name="xarm5/link1" pos="0 -0.0035000000000000001 0.151">
          <inertial pos="-0.00020000000000000001 0.029049999999999999 -0.012330000000000001" quat="0.97895299999999996 -0.202769 -0.0044161699999999996 -0.022726400000000001" mass="2.3820000000000001" diaginertia="0.00569127 0.0053338400000000003 0.0029386500000000001"/>
          <joint name="xarm5/joint1" class="xarm5/size1" pos="0 0.001 0"/>
          <geom name="xarm5//unnamed_geom_1" mesh="xarm5/link1"/>
          <body name="xarm5/link2" pos="-0.0060000000000000001 0.044999999999999998 0.068500000000000005">
            <joint name="xarm5/joint2" class="xarm5/size1" pos="0.0064999999999999997 0 0.049000000000000002" axis="0 1 0" range="-2.0590000000000002 2.0943999999999998"/>
            <geom name="xarm5//unnamed_geom_2" mesh="xarm5/link2"/>
            <body name="xarm5/link3" pos="0.088999999999999996 -0.0050000000000000001 0.17000000000000001">
              <inertial pos="0.046600000000000003 -0.024629999999999999 -0.0076800000000000002" quat="0.91381900000000005 0.289775 0.28148099999999998 -0.041645500000000002" mass="1.6383000000000001" diaginertia="0.0035172100000000002 0.0029408899999999998 0.00195868"/>
              <joint name="xarm5/joint3" class="xarm5/size2" pos="-0.029999999999999999 -0.01 0.16300000000000001" axis="0 1 0"/>
              <geom name="xarm5//unnamed_geom_3" mesh="xarm5/link3"/>
              <body name="xarm5/link4" pos="0.049000000000000002 -0.055 -0.219">
                <inertial pos="0.070470000000000005 -0.11575000000000001 0.012" quat="0.42210799999999998 0.85202599999999995 -0.126025 0.28283199999999997" mass="1.7269000000000001" diaginertia="0.00657137 0.0064794800000000001 0.0018676299999999999"/>
                <geom name="xarm5//unnamed_geom_4" mesh="xarm5/link4"/>
                <body name="xarm5/link5" pos="0.029999999999999999 0.028000000000000001 0">
                  <inertial pos="-0.00032000000000000003 0.016039999999999999 -0.025999999999999999" quat="0.99931099999999995 -0.030445699999999999 0.00057706700000000001 0.0212082" mass="1.3203" diaginertia="0.0053472900000000002 0.0049907600000000003 0.0013489000000000001"/>
                  <joint name="xarm5/joint4" class="xarm5/size3" pos="-0.029999999999999999 -0.014999999999999999 0.036999999999999998" axis="0 1 0"/>
                  <geom name="xarm5//unnamed_geom_5" mesh="xarm5/link5"/>
                  <body name="xarm5/link6" pos="0.045999999999999999 0 -0.056000000000000001">
                    <inertial pos="0.064689999999999998 0.032779999999999997 0.021409999999999998" quat="-0.217672 0.77241899999999997 0.16258 0.57406900000000005" mass="1.325" diaginertia="0.0024542100000000001 0.00221646 0.00107273"/>
                    <joint name="xarm5/joint5" class="xarm5/size3" pos="0.00029999999999999997 -0.0070000000000000001 0" axis="0 0 -1" range="-1.6929700000000001 3.1415899999999999"/>
                    <geom name="xarm5//unnamed_geom_6" mesh="xarm5/link6"/>
                  </body>
                </body>
              </body>
            </body>
          </body>
        </body>
      </body>
    </body>
  </worldbody>
  <actuator>
    <general name="xarm5/act1" class="xarm5/size1" ctrlrange="-3.1415000000000002 3.1415000000000002" joint="xarm5/joint1"/>
    <general name="xarm5/act2" class="xarm5/size1" ctrlrange="-2.0590000000000002 2.0943999999999998" joint="xarm5/joint2"/>
    <general name="xarm5/act3" class="xarm5/size2" ctrlrange="-3.927 0.19198000000000001" joint="xarm5/joint3"/>
    <general name="xarm5/act4" class="xarm5/size3" ctrlrange="-1.6929700000000001 3.1415899999999999" joint="xarm5/joint4"/>
    <general name="xarm5/act5" class="xarm5/size3" joint="xarm5/joint5"/>
  </actuator>
  <keyframe>
    <key name="xarm5/home" qpos="1.571 3.141 1.571 3.141 6.2830000000000004"/>
  </keyframe>
</mujoco>
