<mujoco model="xarm5">
  <compiler angle="radian" autolimits="true" meshdir="assets"/>

  <option integrator="implicitfast"/>

  <asset>
    <material name="white" rgba="1 1 1 1"/>
    <material name="gray" rgba="0.753 0.753 0.753 1"/>
    <material name="black" rgba="0.149 0.149 0.149 1"/>

    <mesh name="link_base" file="link_base.stl" scale="0.001 0.001 0.001"/>
    <mesh name="link1" file="link1.stl" scale="0.001 0.001 0.001"/>
    <mesh name="link2" file="link2.stl" scale="0.001 0.001 0.001"/>
    <mesh name="link3" file="link3.stl" scale="0.001 0.001 0.001"/>
    <mesh name="link4" file="link4.stl" scale="0.001 0.001 0.001"/>
    <mesh name="link5" file="link5.stl" scale="0.001 0.001 0.001"/>
    <mesh name="link6" file="link6.stl" scale="0.001 0.001 0.001"/>
    
    <mesh name="end_tool" file="end_tool.stl"/>
    <mesh name="base_link" file="base_link.stl"/>
    <mesh name="left_outer_knuckle" file="left_outer_knuckle.stl"/>
    <mesh name="left_finger" file="left_finger.stl"/>
    <mesh name="left_inner_knuckle" file="left_inner_knuckle.stl"/>
    <mesh name="right_outer_knuckle" file="right_outer_knuckle.stl"/>
    <mesh name="right_finger" file="right_finger.stl"/>
    <mesh name="right_inner_knuckle" file="right_inner_knuckle.stl"/>
  </asset>

  <default>
    <default class="xarm5">
      <geom type="mesh" material="white"/>
      <joint axis="0 0 1" armature="0.1" range="-6.28319 6.28319" frictionloss="1"/>
      <general biastype="affine" ctrlrange="-6.28319 6.28319"/>
      <default class="size1">
        <joint damping="10"/>
        <general gainprm="1500" biasprm="0 -1500 -150" forcerange="-50 50"/>
      </default>
      <default class="size2">
        <joint damping="5"/>
        <general gainprm="1000" biasprm="0 -1000 -100" forcerange="-30 30"/>
      </default>
      <default class="size3">
        <joint damping="2"/>
        <general gainprm="800" biasprm="0 -800 -80" forcerange="-20 20"/>
      </default>
      <default class="driver">
        <joint range="0 0.85" armature="0.005" damping="0.1" solreflimit="0.005 1"/>
      </default>
      <default class="follower">
        <joint range="0 0.85" solreflimit="0.005 1"/>
      </default>
      <default class="visual">
        <geom type="mesh" contype="0" conaffinity="0" group="2"/>
      </default>
    </default>
  </default>

  <worldbody>
    <body name="link_base" pos="0 0 .12" childclass="xarm5">
        <inertial pos="-0.021131 -0.0016302 0.056488" quat="0.696843 0.20176 0.10388 0.680376" mass="0.88556"
          diaginertia="0.00382023 0.00335282 0.00167725"/>
        <geom mesh="link_base" />
        
        <body name="link1" pos="0 -0.0035 0.151"> 
          <inertial pos="-0.0002 0.02905 -0.01233" quat="0.978953 -0.202769 -0.00441617 -0.0227264" mass="2.382"
          diaginertia="0.00569127 0.00533384 0.00293865"/>
          <joint name="joint1" class="size1"/>
          <geom mesh="link1"/>
          
          <body name="link2" pos="-0.007 0.025 0.0685">
            <inertial pos="0.00022 -0.12856 0.01735" quat="0.50198 0.86483 -0.00778841 0.00483285" mass="1.869"
              diaginertia="0.00959898 0.00937717 0.00201315"/>
            <joint name="joint2" range="-2.059 2.0944" class="size1"/>
            <geom mesh="link2"/>

            <body name="link3" pos="0.089 -0.005 0.17">
            <inertial pos="0.0466 -0.02463 -0.00768" quat="0.913819 0.289775 0.281481 -0.0416455" mass="1.6383"
              diaginertia="0.00351721 0.00294089 0.00195868"/>
            <joint name="joint3" class="size2"/>
            <geom mesh="link3"/>

              <body name="link4" pos="0.049 -0.055 -0.219">
              <inertial pos="0.07047 -0.11575 0.012" quat="0.422108 0.852026 -0.126025 0.282832" mass="1.7269"
                diaginertia="0.00657137 0.00647948 0.00186763"/>
              <joint name="joint4" range="-0.19198 3.927" class="size2"/>
              <geom mesh="link4"/>

                <body name="link5" pos="0.03 0.028 0">
                <inertial pos="-0.00032 0.01604 -0.026" quat="0.999311 -0.0304457 0.000577067 0.0212082" mass="1.3203"
                  diaginertia="0.00534729 0.00499076 0.0013489"/>
                <joint name="joint5" class="size2"/>
                <geom mesh="link5"/>

                  <body name="link6" pos="0.046 0 -0.056">
                  <inertial pos="0.06469 0.03278 0.02141" quat="-0.217672 0.772419 0.16258 0.574069" mass="1.325"
                    diaginertia="0.00245421 0.00221646 0.00107273"/>
                  <joint name="joint6" range="-1.69297 3.14159" class="size3"/>
                  <geom mesh="link6"/>
                  <!-- Gripper -->
                  
                  </body>
                </body>
              </body>
            </body>
          </body>
        </body>
    </body>
  </worldbody>
<!--
  <contact>
    <exclude body1="right_outer_knuckle" body2="right_finger"/>
    <exclude body1="left_outer_knuckle" body2="left_finger"/>
  </contact>

  <tendon>
    <fixed name="split">
      <joint joint="right_driver_joint" coef="0.5"/>
      <joint joint="left_driver_joint" coef="0.5"/>
    </fixed>
  </tendon>

  <equality>
    <joint joint1="left_driver_joint" joint2="right_driver_joint" polycoef="0 1 0 0 0" solref="0.005 1"/>
  </equality>

  <actuator>
    <general name="act1" joint="joint1" class="size1"/>
    <general name="act2" joint="joint2" class="size1" ctrlrange="-2.059 2.0944"/>
    <general name="act3" joint="joint3" class="size2" ctrlrange="-0.19198 3.927"/>
    <general name="act4" joint="joint4" class="size2"/>
    <general name="act5" joint="joint5" class="size3" ctrlrange="-1.69297 3.14159"/>
    <general name="gripper" tendon="split" forcerange="-50 50" ctrlrange="0 255" biastype="affine" gainprm="0.333" biasprm="0 -100 -10"/>
  </actuator>

  <keyframe>
    <key name="home" qpos="0 0 0 0 0 0 0" ctrl="0 0 0 0 0 0"/>
  </keyframe>
  -->
</mujoco>